[2023-06-10 00:26:35,154] {taskinstance.py:1035} INFO - Dependencies all met for <TaskInstance: leads_dbt_models_run.dbt_run manual__2023-06-10T00:16:59.216620+00:00 [queued]>
[2023-06-10 00:26:35,205] {taskinstance.py:1035} INFO - Dependencies all met for <TaskInstance: leads_dbt_models_run.dbt_run manual__2023-06-10T00:16:59.216620+00:00 [queued]>
[2023-06-10 00:26:35,206] {taskinstance.py:1241} INFO - 
--------------------------------------------------------------------------------
[2023-06-10 00:26:35,207] {taskinstance.py:1242} INFO - Starting attempt 3 of 3
[2023-06-10 00:26:35,208] {taskinstance.py:1243} INFO - 
--------------------------------------------------------------------------------
[2023-06-10 00:26:35,251] {taskinstance.py:1262} INFO - Executing <Task(BashOperator): dbt_run> on 2023-06-10 00:16:59.216620+00:00
[2023-06-10 00:26:35,256] {standard_task_runner.py:52} INFO - Started process 33731 to run task
[2023-06-10 00:26:35,263] {standard_task_runner.py:76} INFO - Running: ['***', 'tasks', 'run', 'leads_dbt_models_run', 'dbt_run', 'manual__2023-06-10T00:16:59.216620+00:00', '--job-id', '596', '--raw', '--subdir', 'DAGS_FOLDER/dbt_invoke.py', '--cfg-path', '/tmp/tmp9yth6ggy', '--error-file', '/tmp/tmprww0fog8']
[2023-06-10 00:26:35,271] {standard_task_runner.py:77} INFO - Job 596: Subtask dbt_run
[2023-06-10 00:26:35,371] {logging_mixin.py:109} INFO - Running <TaskInstance: leads_dbt_models_run.dbt_run manual__2023-06-10T00:16:59.216620+00:00 [running]> on host 6ba608d2de6e
[2023-06-10 00:26:35,492] {taskinstance.py:1414} INFO - Exporting the following env vars:
AIRFLOW_CTX_DAG_EMAIL=***
AIRFLOW_CTX_DAG_OWNER=***
AIRFLOW_CTX_DAG_ID=leads_dbt_models_run
AIRFLOW_CTX_TASK_ID=dbt_run
AIRFLOW_CTX_EXECUTION_DATE=2023-06-10T00:16:59.216620+00:00
AIRFLOW_CTX_DAG_RUN_ID=manual__2023-06-10T00:16:59.216620+00:00
[2023-06-10 00:26:35,496] {subprocess.py:62} INFO - Tmp dir root location: 
 /tmp
[2023-06-10 00:26:35,498] {subprocess.py:74} INFO - Running command: ['bash', '-c', 'dbt run --project-dir ../../opt/dbt/leads_data --profiles-dir .. ']
[2023-06-10 00:26:35,511] {subprocess.py:85} INFO - Output:
[2023-06-10 00:26:43,129] {subprocess.py:89} INFO - Running with dbt=0.15.0
[2023-06-10 00:26:48,194] {subprocess.py:89} INFO - Found 2 models, 0 tests, 0 snapshots, 0 analyses, 120 macros, 0 operations, 0 seed files, 0 sources
[2023-06-10 00:26:48,212] {subprocess.py:89} INFO - 
[2023-06-10 00:26:49,141] {subprocess.py:89} INFO - 00:26:49 | Concurrency: 10 threads (target='dev')
[2023-06-10 00:26:49,142] {subprocess.py:89} INFO - 00:26:49 |
[2023-06-10 00:26:49,194] {subprocess.py:89} INFO - 00:26:49 | 1 of 2 START table model public.flatten_leads........................ [RUN]
[2023-06-10 00:26:50,680] {subprocess.py:89} INFO - 00:26:50 | 1 of 2 ERROR creating table model public.flatten_leads............... [[31mERROR[0m in 0.55s]
[2023-06-10 00:26:50,687] {subprocess.py:89} INFO - 00:26:50 | 2 of 2 SKIP relation public.leads_summary............................ [[33mSKIP[0m]
[2023-06-10 00:26:50,751] {subprocess.py:89} INFO - 00:26:50 |
[2023-06-10 00:26:50,753] {subprocess.py:89} INFO - 00:26:50 | Finished running 1 table model, 1 view model in 2.54s.
[2023-06-10 00:26:50,817] {subprocess.py:89} INFO - 
[2023-06-10 00:26:50,819] {subprocess.py:89} INFO - [31mCompleted with 1 error and 0 warnings:[0m
[2023-06-10 00:26:50,821] {subprocess.py:89} INFO - 
[2023-06-10 00:26:50,823] {subprocess.py:89} INFO - [33mDatabase Error in model flatten_leads (models/example/flatten_leads.sql)[0m
[2023-06-10 00:26:50,824] {subprocess.py:89} INFO -   syntax error at or near "WITH"
[2023-06-10 00:26:50,826] {subprocess.py:89} INFO -   LINE 35: WITH sftp_data AS (
[2023-06-10 00:26:50,827] {subprocess.py:89} INFO -            ^
[2023-06-10 00:26:50,829] {subprocess.py:89} INFO -   compiled SQL at target/run/leads_data/example/flatten_leads.sql
[2023-06-10 00:26:50,831] {subprocess.py:89} INFO - 
[2023-06-10 00:26:50,832] {subprocess.py:89} INFO - Done. PASS=1 WARN=0 ERROR=1 SKIP=0 TOTAL=2
[2023-06-10 00:26:52,192] {subprocess.py:93} INFO - Command exited with return code 1
[2023-06-10 00:26:52,196] {taskinstance.py:1686} ERROR - Task failed with exception
Traceback (most recent call last):
  File "/home/airflow/.local/lib/python3.6/site-packages/airflow/models/taskinstance.py", line 1324, in _run_raw_task
    self._execute_task_with_callbacks(context)
  File "/home/airflow/.local/lib/python3.6/site-packages/airflow/models/taskinstance.py", line 1443, in _execute_task_with_callbacks
    result = self._execute_task(context, self.task)
  File "/home/airflow/.local/lib/python3.6/site-packages/airflow/models/taskinstance.py", line 1499, in _execute_task
    result = execute_callable(context=context)
  File "/home/airflow/.local/lib/python3.6/site-packages/airflow/operators/bash.py", line 188, in execute
    f'Bash command failed. The command returned a non-zero exit code {result.exit_code}.'
airflow.exceptions.AirflowException: Bash command failed. The command returned a non-zero exit code 1.
[2023-06-10 00:26:52,233] {taskinstance.py:1280} INFO - Marking task as FAILED. dag_id=leads_dbt_models_run, task_id=dbt_run, execution_date=20230610T001659, start_date=20230610T002635, end_date=20230610T002652
[2023-06-10 00:26:52,313] {logging_mixin.py:109} WARNING - /home/***/.local/lib/python3.6/site-packages/***/utils/email.py:102 PendingDeprecationWarning: Fetching SMTP credentials from configuration variables will be deprecated in a future release. Please set credentials using a connection instead.
[2023-06-10 00:26:52,315] {configuration.py:381} WARNING - section/key [smtp/smtp_user] not found in config
[2023-06-10 00:26:52,316] {email.py:208} INFO - Email alerting: attempt 1
[2023-06-10 00:26:52,338] {configuration.py:381} WARNING - section/key [smtp/smtp_user] not found in config
[2023-06-10 00:26:52,340] {email.py:208} INFO - Email alerting: attempt 1
[2023-06-10 00:26:52,346] {taskinstance.py:1739} ERROR - Failed to send email to: ['***']
Traceback (most recent call last):
  File "/home/airflow/.local/lib/python3.6/site-packages/airflow/models/taskinstance.py", line 1324, in _run_raw_task
    self._execute_task_with_callbacks(context)
  File "/home/airflow/.local/lib/python3.6/site-packages/airflow/models/taskinstance.py", line 1443, in _execute_task_with_callbacks
    result = self._execute_task(context, self.task)
  File "/home/airflow/.local/lib/python3.6/site-packages/airflow/models/taskinstance.py", line 1499, in _execute_task
    result = execute_callable(context=context)
  File "/home/airflow/.local/lib/python3.6/site-packages/airflow/operators/bash.py", line 188, in execute
    f'Bash command failed. The command returned a non-zero exit code {result.exit_code}.'
airflow.exceptions.AirflowException: Bash command failed. The command returned a non-zero exit code 1.

During handling of the above exception, another exception occurred:

Traceback (most recent call last):
  File "/home/airflow/.local/lib/python3.6/site-packages/airflow/models/taskinstance.py", line 2189, in email_alert
    send_email(self.task.email, subject, html_content)
  File "/home/airflow/.local/lib/python3.6/site-packages/airflow/utils/email.py", line 66, in send_email
    **kwargs,
  File "/home/airflow/.local/lib/python3.6/site-packages/airflow/utils/email.py", line 102, in send_email_smtp
    send_mime_email(e_from=smtp_mail_from, e_to=recipients, mime_msg=msg, conn_id=conn_id, dryrun=dryrun)
  File "/home/airflow/.local/lib/python3.6/site-packages/airflow/utils/email.py", line 210, in send_mime_email
    conn = _get_smtp_connection(smtp_host, smtp_port, smtp_timeout, smtp_ssl)
  File "/home/airflow/.local/lib/python3.6/site-packages/airflow/utils/email.py", line 244, in _get_smtp_connection
    else smtplib.SMTP(host=host, port=port, timeout=timeout)
  File "/usr/local/lib/python3.6/smtplib.py", line 251, in __init__
    (code, msg) = self.connect(host, port)
  File "/usr/local/lib/python3.6/smtplib.py", line 336, in connect
    self.sock = self._get_socket(host, port, self.timeout)
  File "/usr/local/lib/python3.6/smtplib.py", line 307, in _get_socket
    self.source_address)
  File "/usr/local/lib/python3.6/socket.py", line 724, in create_connection
    raise err
  File "/usr/local/lib/python3.6/socket.py", line 713, in create_connection
    sock.connect(sa)
OSError: [Errno 99] Cannot assign requested address

During handling of the above exception, another exception occurred:

Traceback (most recent call last):
  File "/home/airflow/.local/lib/python3.6/site-packages/airflow/models/taskinstance.py", line 1737, in handle_failure
    self.email_alert(error)
  File "/home/airflow/.local/lib/python3.6/site-packages/airflow/models/taskinstance.py", line 2191, in email_alert
    send_email(self.task.email, subject, html_content_err)
  File "/home/airflow/.local/lib/python3.6/site-packages/airflow/utils/email.py", line 66, in send_email
    **kwargs,
  File "/home/airflow/.local/lib/python3.6/site-packages/airflow/utils/email.py", line 102, in send_email_smtp
    send_mime_email(e_from=smtp_mail_from, e_to=recipients, mime_msg=msg, conn_id=conn_id, dryrun=dryrun)
  File "/home/airflow/.local/lib/python3.6/site-packages/airflow/utils/email.py", line 210, in send_mime_email
    conn = _get_smtp_connection(smtp_host, smtp_port, smtp_timeout, smtp_ssl)
  File "/home/airflow/.local/lib/python3.6/site-packages/airflow/utils/email.py", line 244, in _get_smtp_connection
    else smtplib.SMTP(host=host, port=port, timeout=timeout)
  File "/usr/local/lib/python3.6/smtplib.py", line 251, in __init__
    (code, msg) = self.connect(host, port)
  File "/usr/local/lib/python3.6/smtplib.py", line 336, in connect
    self.sock = self._get_socket(host, port, self.timeout)
  File "/usr/local/lib/python3.6/smtplib.py", line 307, in _get_socket
    self.source_address)
  File "/usr/local/lib/python3.6/socket.py", line 724, in create_connection
    raise err
  File "/usr/local/lib/python3.6/socket.py", line 713, in create_connection
    sock.connect(sa)
OSError: [Errno 99] Cannot assign requested address
[2023-06-10 00:26:52,394] {standard_task_runner.py:91} ERROR - Failed to execute job 596 for task dbt_run
Traceback (most recent call last):
  File "/home/airflow/.local/lib/python3.6/site-packages/airflow/task/task_runner/standard_task_runner.py", line 85, in _start_by_fork
    args.func(args, dag=self.dag)
  File "/home/airflow/.local/lib/python3.6/site-packages/airflow/cli/cli_parser.py", line 48, in command
    return func(*args, **kwargs)
  File "/home/airflow/.local/lib/python3.6/site-packages/airflow/utils/cli.py", line 92, in wrapper
    return f(*args, **kwargs)
  File "/home/airflow/.local/lib/python3.6/site-packages/airflow/cli/commands/task_command.py", line 292, in task_run
    _run_task_by_selected_method(args, dag, ti)
  File "/home/airflow/.local/lib/python3.6/site-packages/airflow/cli/commands/task_command.py", line 107, in _run_task_by_selected_method
    _run_raw_task(args, ti)
  File "/home/airflow/.local/lib/python3.6/site-packages/airflow/cli/commands/task_command.py", line 184, in _run_raw_task
    error_file=args.error_file,
  File "/home/airflow/.local/lib/python3.6/site-packages/airflow/utils/session.py", line 70, in wrapper
    return func(*args, session=session, **kwargs)
  File "/home/airflow/.local/lib/python3.6/site-packages/airflow/models/taskinstance.py", line 1324, in _run_raw_task
    self._execute_task_with_callbacks(context)
  File "/home/airflow/.local/lib/python3.6/site-packages/airflow/models/taskinstance.py", line 1443, in _execute_task_with_callbacks
    result = self._execute_task(context, self.task)
  File "/home/airflow/.local/lib/python3.6/site-packages/airflow/models/taskinstance.py", line 1499, in _execute_task
    result = execute_callable(context=context)
  File "/home/airflow/.local/lib/python3.6/site-packages/airflow/operators/bash.py", line 188, in execute
    f'Bash command failed. The command returned a non-zero exit code {result.exit_code}.'
airflow.exceptions.AirflowException: Bash command failed. The command returned a non-zero exit code 1.
[2023-06-10 00:26:52,419] {local_task_job.py:154} INFO - Task exited with return code 1
[2023-06-10 00:26:52,526] {local_task_job.py:264} INFO - 0 downstream tasks scheduled from follow-on schedule check
